<mujoco model="atom02">
  <compiler angle="radian" meshdir="../meshes/" eulerseq="zyx" balanceinertia="true"/>
    <option timestep='0.001' iterations='100' solver='PGS' gravity='0 0 -9.81'>
    <flag frictionloss="enable"/>
    </option>
    <size njmax="500" nconmax="100" />

    <visual>
        <quality shadowsize='4096'/>
        <map znear='0.05'/>
    </visual>
    <default>
        <joint limited='true'/>
        <motor ctrllimited='true'/>
        <geom  condim='4' contype="1" conaffinity="15" solref='0.001 2' friction='0.9 0.2 0.2' group="1"/>
        <equality solref='0.001 2'/>
        <default class='visualgeom'>
            <geom material='visualgeom' condim='1' contype='0' conaffinity='0'/>
        </default>
        <default class='obstacle'>
            <geom material='obstacle' condim='3' contype='1' conaffinity='15'/>
        </default>
        <default class='waist_joint_param'>
            <joint  damping="0.01" frictionloss="0.01" armature="0.01"/>
        </default>
        <default class='leg_joint_param'>
            <joint  damping="0.01" frictionloss="0.01" armature="0.01"/>
        </default>
        <default class='arm_joint_param'>
            <joint  damping="0.01" frictionloss="0.01" armature="0.01"/>
        </default>  
    </default>
  <asset>
    <texture type="skybox" builtin="gradient" rgb1="0.3 0.5 0.7" rgb2="0 0 0" width="512" height="512"/>
    <texture name="texplane" type="2d" builtin="checker" rgb1=".2 .3 .4" rgb2=".1 0.15 0.2"
        width="512" height="512" mark="cross" markrgb=".8 .8 .8"/>

    <material name="matplane" reflectance="0." texture="texplane" texrepeat="1 1" texuniform="true"/>

    <material name='obstacle'  rgba='0.9 0.6 0.2 1'/>
    <material name='visualgeom'  rgba='0.5 0.9 0.2 1'/>

    <mesh name="base_link" file="base_link.STL"/>
    <mesh name="left_thigh_pitch_link" file="left_thigh_pitch_link.STL"/>
    <mesh name="left_thigh_roll_link" file="left_thigh_roll_link.STL"/>
    <mesh name="left_thigh_yaw_link" file="left_thigh_yaw_link.STL"/>
    <mesh name="left_knee_link" file="left_knee_link.STL"/>
    <mesh name="left_ankle_pitch_link" file="left_ankle_pitch_link.STL"/>
    <mesh name="left_ankle_roll_link" file="left_ankle_roll_link.STL"/>
    <mesh name="right_thigh_pitch_link" file="right_thigh_pitch_link.STL"/>
    <mesh name="right_thigh_roll_link" file="right_thigh_roll_link.STL"/>
    <mesh name="right_thigh_yaw_link" file="right_thigh_yaw_link.STL"/>
    <mesh name="right_knee_link" file="right_knee_link.STL"/>
    <mesh name="right_ankle_pitch_link" file="right_ankle_pitch_link.STL"/>
    <mesh name="right_ankle_roll_link" file="right_ankle_roll_link.STL"/>
    <mesh name="torso_roll_link" file="torso_roll_link.STL"/>
    <mesh name="torso_yaw_link" file="torso_yaw_link.STL"/>
    <mesh name="left_shoulder_pitch_link" file="left_shoulder_pitch_link.STL"/>
    <mesh name="left_shoulder_roll_link" file="left_shoulder_roll_link.STL"/>
    <mesh name="left_shoulder_yaw_link" file="left_shoulder_yaw_link.STL"/>
    <mesh name="left_elbow_pitch_link" file="left_elbow_pitch_link.STL"/>
    <mesh name="left_elbow_yaw_link" file="left_elbow_yaw_link.STL"/>
    <mesh name="right_shoulder_pitch_link" file="right_shoulder_pitch_link.STL"/>
    <mesh name="right_shoulder_roll_link" file="right_shoulder_roll_link.STL"/>
    <mesh name="right_shoulder_yaw_link" file="right_shoulder_yaw_link.STL"/>
    <mesh name="right_elbow_pitch_link" file="right_elbow_pitch_link.STL"/>
    <mesh name="right_elbow_yaw_link" file="right_elbow_yaw_link.STL"/>

    <hfield name='hf0' nrow='200' ncol='200' size="10 5 0.2 .1"/>
  </asset>
  <worldbody>
    <light directional="true" diffuse=".4 .4 .4" specular="0.1 0.1 0.1" pos="0 0 5.0" dir="0 0 -1" castshadow="false"/>
    <light directional="true" diffuse=".6 .6 .6" specular="0.2 0.2 0.2" pos="0 0 4" dir="0 0 -1"/>
    <geom name="ground" type="plane" size="0 0 1" pos="0.001 0 0" quat="1 0 0 0" material="matplane" condim="1" conaffinity='15' group="0"/>

    <body name="base_link" pos="0 0 0.75">
      <site name='imu' size='0.01' pos='0.0 0 0.0'/>
      <inertial pos="0.0426945929688825 0.00148737267167587 -0.0241809712463922" mass="3.23595958" fullinertia="0.01504054 0.01750647 0.01820607 0.00048618 -0.00504802 -0.00034172"/>
      <joint name="floating_base_joint" type="free" limited="false"/>
      <geom type="mesh" mesh="base_link" rgba="0.75 0.75 0.75 1"/>
      <body name="left_thigh_pitch_link" pos="0.043915 0.1286 -0.036743">
        <inertial pos="0.00433081783795993 -0.00846409127354864 1.15359525446057E-05" mass="1.45950912" fullinertia="0.00636828 0.00186447 0.00614137 0.00082521 0.00001676 0.00003711"/>
        <joint name="left_thigh_pitch_joint" pos="0 0 0" axis="0 1 0" range="-2.862 2.862" class="leg_joint_param"/>
        <geom type="mesh" mesh="left_thigh_pitch_link" class="visualgeom"/>
        <body name="left_thigh_roll_link" pos="0 0 0">
          <inertial pos="0.00427363423171547 -0.0040249982403292 -0.0129865815538047" mass="1.90711030732957" fullinertia="0.02253575 0.02267290 0.00306051 0.00000925 0.00211972 0.00007777"/>
          <joint name="left_thigh_roll_joint" pos="0 0 0" axis="1 0 0" range="-0.1745 2.6878" class="leg_joint_param"/>
          <geom type="mesh" mesh="left_thigh_roll_link" class="visualgeom"/>
          <body name="left_thigh_yaw_link" pos="0.020233 0 0">
            <inertial pos="-0.00897791991505894 0.000916285170142084 -0.313717683033613" mass="2.32668441" fullinertia="0.05527065 0.05610703 0.00449839 0.00022496 0.00609411 0.00147990"/>
            <joint name="left_thigh_yaw_joint" pos="0 0 0" axis="0 0 -1" range="-1.9199 1.9199" class="leg_joint_param"/>
            <geom type="mesh" mesh="left_thigh_yaw_link" class="visualgeom"/>
            <body name="left_knee_link" pos="-0.0259105994324788 0 -0.315911806813306">
              <inertial pos="0.0180038551048904 4.27446807210741E-06 0.143728685313681" mass="2.18421456" fullinertia="0.06382030 0.06250280 0.00564158 0.00136231 -0.00604208 -0.00998488"/>
              <joint name="left_knee_joint" pos="0 0 0" axis="0 -1 0" range="-2.7925 0.2618" class="leg_joint_param"/>
              <geom type="mesh" mesh="left_knee_link" class="visualgeom"/>
              <body name="left_ankle_pitch_link" pos="0.00538908374941682 0 -0.310500012478865">
                <inertial pos="-0.000916659331079805 2.3285817718488E-12 -0.0142487687135151" mass="0.22519575" fullinertia="0.00008717 0.00008949 0.00003727 0.00000000 0.00000141 0.00000000"/>
                <joint name="left_ankle_pitch_joint" pos="0 0 0" axis="0 -1 0" range="-0.5236 0.6981" class="leg_joint_param"/>
                <geom type="mesh" mesh="left_ankle_pitch_link" class="visualgeom"/>
                <body name="left_ankle_roll_link" pos="0.000288640584767348 0 -0.018968626966601">
                  <inertial pos="0.029826 5.0235E-08 -0.032259" mass="0.58290878" fullinertia="0.00066194 0.00212616 0.00177612 0.00000000 -0.00037265 0.00000000"/>
                  <joint name="left_ankle_roll_joint" pos="0 0 0" axis="1 0 0" range="-0.2618 0.2618" class="leg_joint_param"/>
                  <geom type="mesh" mesh="left_ankle_roll_link" rgba="0.898039 0.917647 0.929412 1"/>
                </body>
              </body>
            </body>
          </body>
        </body>
      </body>
      <body name="right_thigh_pitch_link" pos="0.043915 -0.1256 -0.036743">
        <inertial pos="0.00433081783180763 0.0084662133507678 4.58152789528654E-06" mass="1.44712395" fullinertia="0.00635258 0.00184533 0.00611154 -0.00079426 0.00001469 -0.00002816"/>
        <joint name="right_thigh_pitch_joint" pos="0 0 0" axis="0 -1 0" range="-2.862 2.862" class="leg_joint_param"/>
        <geom type="mesh" mesh="right_thigh_pitch_link" class="visualgeom"/>
        <body name="right_thigh_roll_link" pos="0 0 0">
          <inertial pos="0.00428556068904451 0.00402674942751025 -0.012964969034475" mass="1.91914876" fullinertia="0.02217446 0.02233629 0.00316980 -0.00002035 0.00214489 0.00000733"/>
          <joint name="right_thigh_roll_joint" pos="0 0 0" axis="1 0 0" range="-2.6878 0.1745" class="leg_joint_param"/>
          <geom type="mesh" mesh="right_thigh_roll_link" class="visualgeom"/>
          <body name="right_thigh_yaw_link" pos="0.0202328750983638 0 0">
            <inertial pos="-0.00941357789851324 -2.7930899234585E-06 -0.324209334803403" mass="2.32668364" fullinertia="0.05532166 0.05617178 0.00451460 -0.00022101 0.00616549 -0.00149921"/>
            <joint name="right_thigh_yaw_joint" pos="0 0 0" axis="0 0 -1" range="-1.9199 1.9199" class="leg_joint_param"/>
            <geom type="mesh" mesh="right_thigh_yaw_link" class="visualgeom"/>
            <body name="right_knee_link" pos="-0.0259105994325459 0 -0.315911818718635">
              <inertial pos="0.0180136963898656 7.09786177399696E-06 0.143609725581421" mass="2.16342478" fullinertia="0.06328279 0.06198315 0.00561077 -0.00135632 -0.00604122 0.00989178"/>
              <joint name="right_knee_joint" pos="0 0 0" axis="0 1 0" range="-0.2618 2.7925" class="leg_joint_param"/>
              <geom type="mesh" mesh="right_knee_link" class="visualgeom"/>
              <body name="right_ankle_pitch_link" pos="0.00538908374941711 0 -0.310500012478865">
                <inertial pos="-0.000916659331045119 2.32158736679366E-12 -0.0142487568081484" mass="0.22519575" fullinertia="0.00008717 0.00008949 0.00003727 0.00000000 0.00000141 0.00000000"/>
                <joint name="right_ankle_pitch_joint" pos="0 0 0" axis="0 1 0" range="-0.6981 0.5236" class="leg_joint_param"/>
                <geom type="mesh" mesh="right_ankle_pitch_link" class="visualgeom"/>
                <body name="right_ankle_roll_link" pos="0.000288640584765455 0 -0.0189686150614563">
                  <inertial pos="0.0298256266559766 6.51135200202546E-08 -0.0322592152687466" mass="0.58290878" fullinertia="0.00066194 0.00212616 0.00177612 0.00000000 -0.00037265 0.00000000"/>
                  <joint name="right_ankle_roll_joint" pos="0 0 0" axis="1 0 0" range="-0.2618 0.2618" class="leg_joint_param"/>
                  <geom type="mesh" mesh="right_ankle_roll_link" rgba="0.898039 0.917647 0.929412 1"/>
                </body>
              </body>
            </body>
          </body>
        </body>
      </body>
      <body name="torso_roll_link" pos="0.043914999999919 0.00149999982510596 0.0582569795349133">
        <inertial pos="0 0 0" mass="1.50165300" fullinertia="0.00215606 0.00298480 0.00282389 0.00000396 -0.00024047 0.00001154"/>
        <joint name="torso_roll_joint" pos="0 0 0" axis="1 0 0" range="-0.7854 0.7854" class="waist_joint_param"/>
        <geom type="mesh" mesh="torso_roll_link" class="visualgeom"/>
        <body name="torso_yaw_link" pos="0 0 0">
          <inertial pos="0.00399050743843777 6.70363075697678E-05 0.223190244062931" mass="6.55523381" fullinertia="0.15614275 0.14089775 0.02788566 -0.00002117 -0.00127811 0.00017619"/>
          <joint name="torso_yaw_joint" pos="0 0 0" axis="0 0 1" range="-2.6180 3.1415" class="waist_joint_param"/>
          <geom type="mesh" mesh="torso_yaw_link" class="visualgeom"/>
          <body name="left_shoulder_pitch_link" pos="-0.00531236834996837 0 0.257475047221614">
            <inertial pos="0.00572283416827034 0.133486264130114 0.00569460380518322" mass="0.68492195" fullinertia="0.00232037 0.00047561 0.00234234 0.00007858 0.00000491 0.00007987"/>
            <joint name="left_shoulder_pitch_joint" pos="0 0 0" axis="0 0.999048221581858 0.0436193873653277" range="-2.9671 2.6180" class="arm_joint_param"/>
            <geom type="mesh" mesh="left_shoulder_pitch_link" class="visualgeom"/>
            <body name="left_shoulder_roll_link" pos="0 0.157727108635355 0.0064438018083768">
              <inertial pos="0.00952001146745127 0.00560131858747742 -0.0306561060367536" mass="0.69553781" fullinertia="0.00344143 0.00398959 0.00113255 0.00012423 0.00109614 -0.00028597"/>
              <joint name="left_shoulder_roll_joint" pos="0 0 0" axis="1 0 0" range="-0.1745 3.14159" class="arm_joint_param"/>
              <geom type="mesh" mesh="left_shoulder_roll_link" class="visualgeom"/>
              <body name="left_shoulder_yaw_link" pos="0 0.00647177026748297 0.000725276071402214">
                <inertial pos="0.000183998490163938 -0.00664702098894654 -0.159902602188587" mass="1.01870173" fullinertia="0.01118753 0.01115937 0.00081546 0.00001870 -0.00056633 -0.00024166"/>
                <joint name="left_shoulder_yaw_joint" pos="0 0 0" axis="0 0 -1" range="-3.14159 3.14159" class="arm_joint_param"/>
                <geom type="mesh" mesh="left_shoulder_yaw_link" class="visualgeom"/>
                <body name="left_elbow_pitch_link" pos="0.00950066749573248 0.000428960666849831 -0.230024901410875">
                  <inertial pos="0.0444173770841133 -0.0083983002628778 -0.0104099602928093" mass="0.88600228" fullinertia="0.00318853 0.00463900 0.00712691 -0.00198012 -0.00033737 0.00022460"/>
                  <joint name="left_elbow_pitch_joint" pos="0 0 0" axis="0 -1 0" range="-2 1" class="arm_joint_param"/>
                  <geom type="mesh" mesh="left_elbow_pitch_link" class="visualgeom"/>
                  <body name="left_elbow_yaw_link" pos="0 0 -0.0133504827638016">
                    <inertial pos="0.227394242045541 -0.00540734423351369 0.00547955819471335" mass="0.23249655" fullinertia="0.00012284 0.00061106 0.00059711 -0.00000164 0.00004620 -0.00000022"/>
                    <joint name="left_elbow_yaw_joint" pos="0 0 0" axis="1 0 0" range="-3.14159 3.14159" class="arm_joint_param"/>
                    <geom type="mesh" mesh="left_elbow_yaw_link" class="visualgeom"/>
                  </body>
                </body>
              </body>
            </body>
          </body>
          <body name="right_shoulder_pitch_link" pos="-0.00531236834996837 0 0.257475047221614">
            <inertial pos="-0.00567538717138532 -0.133486276497267 0.00569432899053771" mass="0.68494995" fullinertia="0.00232759 0.00047882 0.00235078 -0.00008802 0.00000210 -0.00008489"/>
            <joint name="right_shoulder_pitch_joint" pos="0 0 0" axis="0 -0.999048221581858 0.0436193873653299" range="-2.6180 2.9671" class="arm_joint_param"/>
            <geom type="mesh" mesh="right_shoulder_pitch_link" class="visualgeom"/>
            <body name="right_shoulder_roll_link" pos="0 -0.157731572169751 0.00634362168986959">
              <inertial pos="-0.00952140798561743 -0.00560123236864984 -0.0306561043273919" mass="0.70646494" fullinertia="0.00346702 0.00404638 0.00116652 0.00012320 0.00111110 0.00028701"/>
              <joint name="right_shoulder_roll_joint" pos="0 0 0" axis="1 0 0" range="-3.14159 0.1745" class="arm_joint_param"/>
              <geom type="mesh" mesh="right_shoulder_roll_link" class="visualgeom"/>
              <body name="right_shoulder_yaw_link" pos="0 -0.00647168056291525 0.000825647150946768">
                <inertial pos="0.000184500652539638 -0.00664702098052161 -0.160002971035617" mass="1.02101321" fullinertia="0.01119198 0.01116463 0.00081899 -0.00000006 -0.00058066 0.00003992"/>
                <joint name="right_shoulder_yaw_joint" pos="0 0 0" axis="0 0 -1" range="-3.14159 3.14159" class="arm_joint_param"/>
                <geom type="mesh" mesh="right_shoulder_yaw_link" class="visualgeom"/>
                <body name="right_elbow_pitch_link" pos="0.00949985837207234 -0.000428960670245448 -0.230025092371912">
                  <inertial pos="0.0444195121887475 -0.00839829362329991 -0.0105100533330512" mass="0.88408116" fullinertia="0.00136198 0.00467022 0.00510726 0.00130205 -0.00073590 -0.00026526"/>
                  <joint name="right_elbow_pitch_joint" pos="0 0 0" axis="0 1 0" range="-1 2" class="arm_joint_param"/>
                  <geom type="mesh" mesh="right_elbow_pitch_link" class="visualgeom"/>
                  <body name="right_elbow_yaw_link" pos="0 0 -0.0133504827638016">
                    <inertial pos="0.227397964445097 0.00372300928214719 0.00537944992731798" mass="0.23249633" fullinertia="0.00011840 0.00054627 0.00053677 0.00000110 -0.00000236 0.00000005"/>
                    <joint name="right_elbow_yaw_joint" pos="0 0 0" axis="1 0 0" range="-3.14159 3.14159" class="arm_joint_param"/>
                    <geom type="mesh" mesh="right_elbow_yaw_link" class="visualgeom"/>
                  </body>
                </body>
              </body>
            </body>
          </body>
        </body>
      </body>
    </body>

  </worldbody>

  <actuator>
    <motor name="left_thigh_yaw_joint" joint="left_thigh_yaw_joint" gear="1" ctrllimited="true" ctrlrange="-200 200"/>
    <motor name="left_thigh_roll_joint" joint="left_thigh_roll_joint" gear="1" ctrllimited="true" ctrlrange="-200 200"/>
    <motor name="left_thigh_pitch_joint" joint="left_thigh_pitch_joint" gear="1" ctrllimited="true" ctrlrange="-200 200"/>
    <motor name="left_knee_joint" joint="left_knee_joint" gear="1" ctrllimited="true" ctrlrange="-200 200"/>
    <motor name="left_ankle_pitch_joint" joint="left_ankle_pitch_joint" gear="1" ctrllimited="true" ctrlrange="-200 200"/>
    <motor name="left_ankle_roll_joint" joint="left_ankle_roll_joint" gear="1" ctrllimited="true" ctrlrange="-200 200"/>
    <motor name="right_thigh_yaw_joint" joint="right_thigh_yaw_joint" gear="1" ctrllimited="true" ctrlrange="-200 200"/>
    <motor name="right_thigh_roll_joint" joint="right_thigh_roll_joint" gear="1" ctrllimited="true" ctrlrange="-200 200"/>
    <motor name="right_thigh_pitch_joint" joint="right_thigh_pitch_joint" gear="1" ctrllimited="true" ctrlrange="-200 200"/>
    <motor name="right_knee_joint" joint="right_knee_joint" gear="1" ctrllimited="true" ctrlrange="-200 200"/>
    <motor name="right_ankle_pitch_joint" joint="right_ankle_pitch_joint" gear="1" ctrllimited="true" ctrlrange="-200 200"/>
    <motor name="right_ankle_roll_joint" joint="right_ankle_roll_joint" gear="1" ctrllimited="true" ctrlrange="-200 200"/>
    <motor name="torso_roll_joint" joint="torso_roll_joint" gear="1" ctrllimited="true" ctrlrange="-200 200"/>
    <motor name="torso_yaw_joint" joint="torso_yaw_joint" gear="1" ctrllimited="true" ctrlrange="-200 200"/>
    <motor name="left_shoulder_pitch_joint" joint="left_shoulder_pitch_joint" gear="1" ctrllimited="true" ctrlrange="-200 200"/>
    <motor name="left_shoulder_roll_joint" joint="left_shoulder_roll_joint" gear="1" ctrllimited="true" ctrlrange="-200 200"/>
    <motor name="left_shoulder_yaw_joint" joint="left_shoulder_yaw_joint" gear="1" ctrllimited="true" ctrlrange="-200 200"/>
    <motor name="left_elbow_pitch_joint" joint="left_elbow_pitch_joint" gear="1" ctrllimited="true" ctrlrange="-200 200"/>
    <motor name="left_elbow_yaw_joint" joint="left_elbow_yaw_joint" gear="1" ctrllimited="true" ctrlrange="-200 200"/>
    <motor name="right_shoulder_pitch_joint" joint="right_shoulder_pitch_joint" gear="1" ctrllimited="true" ctrlrange="-200 200"/>
    <motor name="right_shoulder_roll_joint" joint="right_shoulder_roll_joint" gear="1" ctrllimited="true" ctrlrange="-200 200"/>
    <motor name="right_shoulder_yaw_joint" joint="right_shoulder_yaw_joint" gear="1" ctrllimited="true" ctrlrange="-200 200"/>
    <motor name="right_elbow_pitch_joint" joint="right_elbow_pitch_joint" gear="1" ctrllimited="true" ctrlrange="-200 200"/>
    <motor name="right_elbow_yaw_joint" joint="right_elbow_yaw_joint" gear="1" ctrllimited="true" ctrlrange="-200 200"/>

  </actuator>

     <sensor>
        <actuatorpos name='left_thigh_yaw_p' actuator='left_thigh_yaw_joint' user='13'/>
        <actuatorpos name='left_thigh_roll_p' actuator='left_thigh_roll_joint' user='13'/>
        <actuatorpos name='left_thigh_pitch_p' actuator='left_thigh_pitch_joint' user='13'/>
        <actuatorpos name='left_knee_p' actuator='left_knee_joint' user='13'/>
        <actuatorpos name='left_ankle_pitch_p' actuator='left_ankle_pitch_joint' user='13'/>
        <actuatorpos name='left_ankle_roll_p' actuator='left_ankle_roll_joint' user='13'/>
        <actuatorpos name='right_thigh_yaw_p' actuator='right_thigh_yaw_joint' user='13'/>
        <actuatorpos name='right_thigh_roll_p' actuator='right_thigh_roll_joint' user='13'/>
        <actuatorpos name='right_thigh_pitch_p' actuator='right_thigh_pitch_joint' user='13'/>
        <actuatorpos name='right_knee_p' actuator='right_knee_joint' user='13'/>
        <actuatorpos name='right_ankle_pitch_p' actuator='right_ankle_pitch_joint' user='13'/>
        <actuatorpos name='right_ankle_roll_p' actuator='right_ankle_roll_joint' user='13'/>
        <actuatorpos name='torso_roll_p' actuator='torso_roll_joint' user='13'/>
        <actuatorpos name='torso_yaw_p' actuator='torso_yaw_joint' user='13'/>
        <actuatorpos name='left_shoulder_pitch_p' actuator='left_shoulder_pitch_joint' user='13'/>
        <actuatorpos name='left_shoulder_roll_p' actuator='left_shoulder_roll_joint' user='13'/>
        <actuatorpos name='left_shoulder_yaw_p' actuator='left_shoulder_yaw_joint' user='13'/>
        <actuatorpos name='left_elbow_pitch_p' actuator='left_elbow_pitch_joint' user='13'/>
        <actuatorpos name='left_elbow_yaw_p' actuator='left_elbow_yaw_joint' user='13'/>
        <actuatorpos name='right_shoulder_pitch_p' actuator='right_shoulder_pitch_joint' user='13'/>
        <actuatorpos name='right_shoulder_roll_p' actuator='right_shoulder_roll_joint' user='13'/>
        <actuatorpos name='right_shoulder_yaw_p' actuator='right_shoulder_yaw_joint' user='13'/>
        <actuatorpos name='right_elbow_pitch_p' actuator='right_elbow_pitch_joint' user='13'/>
        <actuatorpos name='right_elbow_yaw_p' actuator='right_elbow_yaw_joint' user='13'/>
        <actuatorvel name='left_thigh_yaw_v' actuator='left_thigh_yaw_joint' user='13'/>
        <actuatorvel name='left_thigh_roll_v' actuator='left_thigh_roll_joint' user='13'/>
        <actuatorvel name='left_thigh_pitch_v' actuator='left_thigh_pitch_joint' user='13'/>
        <actuatorvel name='left_knee_v' actuator='left_knee_joint' user='13'/>
        <actuatorvel name='left_ankle_pitch_v' actuator='left_ankle_pitch_joint' user='13'/>
        <actuatorvel name='left_ankle_roll_v' actuator='left_ankle_roll_joint' user='13'/>
        <actuatorvel name='right_thigh_yaw_v' actuator='right_thigh_yaw_joint' user='13'/>
        <actuatorvel name='right_thigh_roll_v' actuator='right_thigh_roll_joint' user='13'/>
        <actuatorvel name='right_thigh_pitch_v' actuator='right_thigh_pitch_joint' user='13'/>
        <actuatorvel name='right_knee_v' actuator='right_knee_joint' user='13'/>
        <actuatorvel name='right_ankle_pitch_v' actuator='right_ankle_pitch_joint' user='13'/>
        <actuatorvel name='right_ankle_roll_v' actuator='right_ankle_roll_joint' user='13'/>
        <actuatorvel name='torso_roll_v' actuator='torso_roll_joint' user='13'/>
        <actuatorvel name='torso_yaw_v' actuator='torso_yaw_joint' user='13'/>
        <actuatorvel name='left_shoulder_pitch_v' actuator='left_shoulder_pitch_joint' user='13'/>
        <actuatorvel name='left_shoulder_roll_v' actuator='left_shoulder_roll_joint' user='13'/>
        <actuatorvel name='left_shoulder_yaw_v' actuator='left_shoulder_yaw_joint' user='13'/>
        <actuatorvel name='left_elbow_pitch_v' actuator='left_elbow_pitch_joint' user='13'/>
        <actuatorvel name='left_elbow_yaw_v' actuator='left_elbow_yaw_joint' user='13'/>
        <actuatorvel name='right_shoulder_pitch_v' actuator='right_shoulder_pitch_joint' user='13'/>
        <actuatorvel name='right_shoulder_roll_v' actuator='right_shoulder_roll_joint' user='13'/>
        <actuatorvel name='right_shoulder_yaw_v' actuator='right_shoulder_yaw_joint' user='13'/>
        <actuatorvel name='right_elbow_pitch_v' actuator='right_elbow_pitch_joint' user='13'/>
        <actuatorvel name='right_elbow_yaw_v' actuator='right_elbow_yaw_joint' user='13'/>
        <actuatorfrc name='left_thigh_yaw_f' actuator='left_thigh_yaw_joint' user='13' noise='1e-3'/>
        <actuatorfrc name='left_thigh_roll_f' actuator='left_thigh_roll_joint' user='13' noise='1e-3'/>
        <actuatorfrc name='left_thigh_pitch_f' actuator='left_thigh_pitch_joint' user='13' noise='1e-3'/>
        <actuatorfrc name='left_knee_f' actuator='left_knee_joint' user='13' noise='1e-3'/>
        <actuatorfrc name='left_ankle_pitch_f' actuator='left_ankle_pitch_joint' user='13' noise='1e-3'/>
        <actuatorfrc name='left_ankle_roll_f' actuator='left_ankle_roll_joint' user='13' noise='1e-3'/>
        <actuatorfrc name='right_thigh_yaw_f' actuator='right_thigh_yaw_joint' user='13' noise='1e-3'/>
        <actuatorfrc name='right_thigh_roll_f' actuator='right_thigh_roll_joint' user='13' noise='1e-3'/>
        <actuatorfrc name='right_thigh_pitch_f' actuator='right_thigh_pitch_joint' user='13' noise='1e-3'/>
        <actuatorfrc name='right_knee_f' actuator='right_knee_joint' user='13' noise='1e-3'/>
        <actuatorfrc name='right_ankle_pitch_f' actuator='right_ankle_pitch_joint' user='13' noise='1e-3'/>
        <actuatorfrc name='right_ankle_roll_f' actuator='right_ankle_roll_joint' user='13' noise='1e-3'/>
        <actuatorfrc name='torso_roll_f' actuator='torso_roll_joint' user='13' noise='1e-3'/>
        <actuatorfrc name='torso_yaw_f' actuator='torso_yaw_joint' user='13' noise='1e-3'/>
        <actuatorfrc name='left_shoulder_pitch_f' actuator='left_shoulder_pitch_joint' user='13' noise='1e-3'/>
        <actuatorfrc name='left_shoulder_roll_f' actuator='left_shoulder_roll_joint' user='13' noise='1e-3'/>
        <actuatorfrc name='left_shoulder_yaw_f' actuator='left_shoulder_yaw_joint' user='13' noise='1e-3'/>
        <actuatorfrc name='left_elbow_pitch_f' actuator='left_elbow_pitch_joint' user='13' noise='1e-3'/>
        <actuatorfrc name='left_elbow_yaw_f' actuator='left_elbow_yaw_joint' user='13' noise='1e-3'/>
        <actuatorfrc name='right_shoulder_pitch_f' actuator='right_shoulder_pitch_joint' user='13' noise='1e-3'/>
        <actuatorfrc name='right_shoulder_roll_f' actuator='right_shoulder_roll_joint' user='13' noise='1e-3'/>
        <actuatorfrc name='right_shoulder_yaw_f' actuator='right_shoulder_yaw_joint' user='13' noise='1e-3'/>
        <actuatorfrc name='right_elbow_pitch_f' actuator='right_elbow_pitch_joint' user='13' noise='1e-3'/>
        <actuatorfrc name='right_elbow_yaw_f' actuator='right_elbow_yaw_joint' user='13' noise='1e-3'/>

        <framequat     name='orientation' objtype='site' noise='0.001' objname='imu'/>
        <framepos     name='position' objtype='site' noise='0.001' objname='imu'/>
        <gyro          name='angular-velocity'    site='imu' noise='0.005' cutoff='34.9'/>
        <velocimeter   name='linear-velocity'     site='imu' noise='0.001' cutoff='30'/>
        <accelerometer name='linear-acceleration' site='imu' noise='0.005' cutoff='157'/>
        <magnetometer  name='magnetometer'        site='imu'/>

    </sensor>
    <visual>
        <global offwidth="1920" offheight="1080"/>
    </visual>
</mujoco>

